2019-02-05 22:20:25,785 ERROR: Exception on /admin/department [GET] [in /home/holger/git/md_length/venv/lib/python3.5/site-packages/flask/app.py:1761]
Traceback (most recent call last):
  File "/home/holger/git/md_length/venv/lib/python3.5/site-packages/flask/app.py", line 2292, in wsgi_app
    response = self.full_dispatch_request()
  File "/home/holger/git/md_length/venv/lib/python3.5/site-packages/flask/app.py", line 1815, in full_dispatch_request
    rv = self.handle_user_exception(e)
  File "/home/holger/git/md_length/venv/lib/python3.5/site-packages/flask/app.py", line 1718, in handle_user_exception
    reraise(exc_type, exc_value, tb)
  File "/home/holger/git/md_length/venv/lib/python3.5/site-packages/flask/_compat.py", line 35, in reraise
    raise value
  File "/home/holger/git/md_length/venv/lib/python3.5/site-packages/flask/app.py", line 1813, in full_dispatch_request
    rv = self.dispatch_request()
  File "/home/holger/git/md_length/venv/lib/python3.5/site-packages/flask/app.py", line 1799, in dispatch_request
    return self.view_functions[rule.endpoint](**req.view_args)
  File "/home/holger/git/md_length/app/admin/routes.py", line 63, in get_department_list
    data = Department.query.order_by(Department.id).all()
  File "/home/holger/git/md_length/venv/lib/python3.5/site-packages/flask_sqlalchemy/__init__.py", line 512, in __get__
    mapper = orm.class_mapper(type)
  File "/home/holger/git/md_length/venv/lib/python3.5/site-packages/sqlalchemy/orm/base.py", line 421, in class_mapper
    mapper = _inspect_mapped_class(class_, configure=configure)
  File "/home/holger/git/md_length/venv/lib/python3.5/site-packages/sqlalchemy/orm/base.py", line 400, in _inspect_mapped_class
    mapper._configure_all()
  File "/home/holger/git/md_length/venv/lib/python3.5/site-packages/sqlalchemy/orm/mapper.py", line 1276, in _configure_all
    configure_mappers()
  File "/home/holger/git/md_length/venv/lib/python3.5/site-packages/sqlalchemy/orm/mapper.py", line 3033, in configure_mappers
    mapper._post_configure_properties()
  File "/home/holger/git/md_length/venv/lib/python3.5/site-packages/sqlalchemy/orm/mapper.py", line 1832, in _post_configure_properties
    prop.init()
  File "/home/holger/git/md_length/venv/lib/python3.5/site-packages/sqlalchemy/orm/interfaces.py", line 183, in init
    self.do_init()
  File "/home/holger/git/md_length/venv/lib/python3.5/site-packages/sqlalchemy/orm/relationships.py", line 1662, in do_init
    self._generate_backref()
  File "/home/holger/git/md_length/venv/lib/python3.5/site-packages/sqlalchemy/orm/relationships.py", line 1852, in _generate_backref
    (backref_key, self, m))
sqlalchemy.exc.ArgumentError: Error creating backref 'users' on relationship 'User.departments': property of that name exists on mapper 'Mapper|Department|department'
2019-02-05 22:22:28,266 INFO: Length dep. server startup [in /home/holger/git/md_length/app/__init__.py:73]
2019-02-05 22:22:31,063 ERROR: Exception on /admin/department [GET] [in /home/holger/git/md_length/venv/lib/python3.5/site-packages/flask/app.py:1761]
Traceback (most recent call last):
  File "/home/holger/git/md_length/venv/lib/python3.5/site-packages/flask/app.py", line 2292, in wsgi_app
    response = self.full_dispatch_request()
  File "/home/holger/git/md_length/venv/lib/python3.5/site-packages/flask/app.py", line 1815, in full_dispatch_request
    rv = self.handle_user_exception(e)
  File "/home/holger/git/md_length/venv/lib/python3.5/site-packages/flask/app.py", line 1718, in handle_user_exception
    reraise(exc_type, exc_value, tb)
  File "/home/holger/git/md_length/venv/lib/python3.5/site-packages/flask/_compat.py", line 35, in reraise
    raise value
  File "/home/holger/git/md_length/venv/lib/python3.5/site-packages/flask/app.py", line 1813, in full_dispatch_request
    rv = self.dispatch_request()
  File "/home/holger/git/md_length/venv/lib/python3.5/site-packages/flask/app.py", line 1799, in dispatch_request
    return self.view_functions[rule.endpoint](**req.view_args)
  File "/home/holger/git/md_length/app/admin/routes.py", line 63, in get_department_list
    data = Department.query.order_by(Department.id).all()
  File "/home/holger/git/md_length/venv/lib/python3.5/site-packages/flask_sqlalchemy/__init__.py", line 512, in __get__
    mapper = orm.class_mapper(type)
  File "/home/holger/git/md_length/venv/lib/python3.5/site-packages/sqlalchemy/orm/base.py", line 421, in class_mapper
    mapper = _inspect_mapped_class(class_, configure=configure)
  File "/home/holger/git/md_length/venv/lib/python3.5/site-packages/sqlalchemy/orm/base.py", line 400, in _inspect_mapped_class
    mapper._configure_all()
  File "/home/holger/git/md_length/venv/lib/python3.5/site-packages/sqlalchemy/orm/mapper.py", line 1276, in _configure_all
    configure_mappers()
  File "/home/holger/git/md_length/venv/lib/python3.5/site-packages/sqlalchemy/orm/mapper.py", line 3033, in configure_mappers
    mapper._post_configure_properties()
  File "/home/holger/git/md_length/venv/lib/python3.5/site-packages/sqlalchemy/orm/mapper.py", line 1832, in _post_configure_properties
    prop.init()
  File "/home/holger/git/md_length/venv/lib/python3.5/site-packages/sqlalchemy/orm/interfaces.py", line 183, in init
    self.do_init()
  File "/home/holger/git/md_length/venv/lib/python3.5/site-packages/sqlalchemy/orm/relationships.py", line 1662, in do_init
    self._generate_backref()
  File "/home/holger/git/md_length/venv/lib/python3.5/site-packages/sqlalchemy/orm/relationships.py", line 1852, in _generate_backref
    (backref_key, self, m))
sqlalchemy.exc.ArgumentError: Error creating backref 'departments' on relationship 'Department.users': property of that name exists on mapper 'Mapper|User|user'
2019-02-05 22:23:26,845 INFO: Length dep. server startup [in /home/holger/git/md_length/app/__init__.py:73]
2019-02-05 22:23:46,669 ERROR: Exception on /admin/department [POST] [in /home/holger/git/md_length/venv/lib/python3.5/site-packages/flask/app.py:1761]
Traceback (most recent call last):
  File "/home/holger/git/md_length/venv/lib/python3.5/site-packages/flask/app.py", line 2292, in wsgi_app
    response = self.full_dispatch_request()
  File "/home/holger/git/md_length/venv/lib/python3.5/site-packages/flask/app.py", line 1815, in full_dispatch_request
    rv = self.handle_user_exception(e)
  File "/home/holger/git/md_length/venv/lib/python3.5/site-packages/flask/app.py", line 1718, in handle_user_exception
    reraise(exc_type, exc_value, tb)
  File "/home/holger/git/md_length/venv/lib/python3.5/site-packages/flask/_compat.py", line 35, in reraise
    raise value
  File "/home/holger/git/md_length/venv/lib/python3.5/site-packages/flask/app.py", line 1813, in full_dispatch_request
    rv = self.dispatch_request()
  File "/home/holger/git/md_length/venv/lib/python3.5/site-packages/flask/app.py", line 1799, in dispatch_request
    return self.view_functions[rule.endpoint](**req.view_args)
  File "/home/holger/git/md_length/app/admin/routes.py", line 86, in add_department
    dep.from_dict(**json_obj)
  File "/home/holger/git/md_length/app/base_model.py", line 183, in from_dict
    and query.filter_by(id=item["id"])
AttributeError: 'InstrumentedList' object has no attribute 'filter_by'
2019-02-06 07:01:59,202 INFO: Length dep. server startup [in /home/holger/git/md_length/app/__init__.py:73]
2019-02-06 07:02:15,782 ERROR: Exception on /admin/department [POST] [in /home/holger/git/md_length/venv/lib/python3.5/site-packages/flask/app.py:1761]
Traceback (most recent call last):
  File "/home/holger/git/md_length/venv/lib/python3.5/site-packages/flask/app.py", line 2292, in wsgi_app
    response = self.full_dispatch_request()
  File "/home/holger/git/md_length/venv/lib/python3.5/site-packages/flask/app.py", line 1815, in full_dispatch_request
    rv = self.handle_user_exception(e)
  File "/home/holger/git/md_length/venv/lib/python3.5/site-packages/flask/app.py", line 1718, in handle_user_exception
    reraise(exc_type, exc_value, tb)
  File "/home/holger/git/md_length/venv/lib/python3.5/site-packages/flask/_compat.py", line 35, in reraise
    raise value
  File "/home/holger/git/md_length/venv/lib/python3.5/site-packages/flask/app.py", line 1813, in full_dispatch_request
    rv = self.dispatch_request()
  File "/home/holger/git/md_length/venv/lib/python3.5/site-packages/flask/app.py", line 1799, in dispatch_request
    return self.view_functions[rule.endpoint](**req.view_args)
  File "/home/holger/git/md_length/app/admin/routes.py", line 86, in add_department
    dep.from_dict(**json_obj)
  File "/home/holger/git/md_length/app/base_model.py", line 183, in from_dict
    and query.filter_by(id=item["id"])
AttributeError: 'InstrumentedList' object has no attribute 'filter_by'
2019-02-06 07:06:22,914 INFO: Length dep. server startup [in /home/holger/git/md_length/app/__init__.py:73]
