2019-02-06 07:06:39,315 ERROR: Exception on /admin/department [POST] [in /home/holger/git/md_length/venv/lib/python3.5/site-packages/flask/app.py:1761]
Traceback (most recent call last):
  File "/home/holger/git/md_length/venv/lib/python3.5/site-packages/flask/app.py", line 2292, in wsgi_app
    response = self.full_dispatch_request()
  File "/home/holger/git/md_length/venv/lib/python3.5/site-packages/flask/app.py", line 1815, in full_dispatch_request
    rv = self.handle_user_exception(e)
  File "/home/holger/git/md_length/venv/lib/python3.5/site-packages/flask/app.py", line 1718, in handle_user_exception
    reraise(exc_type, exc_value, tb)
  File "/home/holger/git/md_length/venv/lib/python3.5/site-packages/flask/_compat.py", line 35, in reraise
    raise value
  File "/home/holger/git/md_length/venv/lib/python3.5/site-packages/flask/app.py", line 1813, in full_dispatch_request
    rv = self.dispatch_request()
  File "/home/holger/git/md_length/venv/lib/python3.5/site-packages/flask/app.py", line 1799, in dispatch_request
    return self.view_functions[rule.endpoint](**req.view_args)
  File "/home/holger/git/md_length/app/admin/routes.py", line 86, in add_department
    dep.from_dict(**json_obj)
  File "/home/holger/git/md_length/app/base_model.py", line 183, in from_dict
    and query.filter_by(id=item["id"])
  File "/home/holger/git/md_length/venv/lib/python3.5/site-packages/sqlalchemy/orm/query.py", line 1690, in filter_by
    return self.filter(sql.and_(*clauses))
  File "<string>", line 2, in filter
  File "/home/holger/git/md_length/venv/lib/python3.5/site-packages/sqlalchemy/orm/base.py", line 198, in generate
    self = args[0]._clone()
  File "/home/holger/git/md_length/venv/lib/python3.5/site-packages/sqlalchemy/orm/dynamic.py", line 289, in _clone
    orm_util.instance_str(instance), self.attr.key))
sqlalchemy.orm.exc.DetachedInstanceError: Parent instance <Department at 0x7f9543511b38> is not bound to a Session, and no contextual session is established; lazy load operation of attribute 'users' cannot proceed (Background on this error at: http://sqlalche.me/e/bhk3)
2019-02-06 07:10:26,508 INFO: Length dep. server startup [in /home/holger/git/md_length/app/__init__.py:73]
2019-02-06 07:10:34,982 ERROR: Exception on /admin/department [POST] [in /home/holger/git/md_length/venv/lib/python3.5/site-packages/flask/app.py:1761]
Traceback (most recent call last):
  File "/home/holger/git/md_length/venv/lib/python3.5/site-packages/flask/app.py", line 2292, in wsgi_app
    response = self.full_dispatch_request()
  File "/home/holger/git/md_length/venv/lib/python3.5/site-packages/flask/app.py", line 1815, in full_dispatch_request
    rv = self.handle_user_exception(e)
  File "/home/holger/git/md_length/venv/lib/python3.5/site-packages/flask/app.py", line 1718, in handle_user_exception
    reraise(exc_type, exc_value, tb)
  File "/home/holger/git/md_length/venv/lib/python3.5/site-packages/flask/_compat.py", line 35, in reraise
    raise value
  File "/home/holger/git/md_length/venv/lib/python3.5/site-packages/flask/app.py", line 1813, in full_dispatch_request
    rv = self.dispatch_request()
  File "/home/holger/git/md_length/venv/lib/python3.5/site-packages/flask/app.py", line 1799, in dispatch_request
    return self.view_functions[rule.endpoint](**req.view_args)
  File "/home/holger/git/md_length/app/admin/routes.py", line 86, in add_department
    dep.from_dict(**json_obj)
  File "/home/holger/git/md_length/app/base_model.py", line 183, in from_dict
    and query.filter_by(id=item["id"])
  File "/home/holger/git/md_length/venv/lib/python3.5/site-packages/sqlalchemy/orm/query.py", line 1690, in filter_by
    return self.filter(sql.and_(*clauses))
  File "<string>", line 2, in filter
  File "/home/holger/git/md_length/venv/lib/python3.5/site-packages/sqlalchemy/orm/base.py", line 198, in generate
    self = args[0]._clone()
  File "/home/holger/git/md_length/venv/lib/python3.5/site-packages/sqlalchemy/orm/dynamic.py", line 289, in _clone
    orm_util.instance_str(instance), self.attr.key))
sqlalchemy.orm.exc.DetachedInstanceError: Parent instance <Department at 0x7f98e0d58ba8> is not bound to a Session, and no contextual session is established; lazy load operation of attribute 'users' cannot proceed (Background on this error at: http://sqlalche.me/e/bhk3)
2019-02-06 07:13:12,125 INFO: Length dep. server startup [in /home/holger/git/md_length/app/__init__.py:73]
2019-02-06 07:13:20,351 ERROR: Exception on /admin/department [POST] [in /home/holger/git/md_length/venv/lib/python3.5/site-packages/flask/app.py:1761]
Traceback (most recent call last):
  File "/home/holger/git/md_length/venv/lib/python3.5/site-packages/flask/app.py", line 2292, in wsgi_app
    response = self.full_dispatch_request()
  File "/home/holger/git/md_length/venv/lib/python3.5/site-packages/flask/app.py", line 1815, in full_dispatch_request
    rv = self.handle_user_exception(e)
  File "/home/holger/git/md_length/venv/lib/python3.5/site-packages/flask/app.py", line 1718, in handle_user_exception
    reraise(exc_type, exc_value, tb)
  File "/home/holger/git/md_length/venv/lib/python3.5/site-packages/flask/_compat.py", line 35, in reraise
    raise value
  File "/home/holger/git/md_length/venv/lib/python3.5/site-packages/flask/app.py", line 1813, in full_dispatch_request
    rv = self.dispatch_request()
  File "/home/holger/git/md_length/venv/lib/python3.5/site-packages/flask/app.py", line 1799, in dispatch_request
    return self.view_functions[rule.endpoint](**req.view_args)
  File "/home/holger/git/md_length/app/admin/routes.py", line 86, in add_department
    dep.from_dict(**json_obj)
  File "/home/holger/git/md_length/app/base_model.py", line 183, in from_dict
    and query.filter_by(id=item["id"])
  File "/home/holger/git/md_length/venv/lib/python3.5/site-packages/sqlalchemy/orm/query.py", line 1690, in filter_by
    return self.filter(sql.and_(*clauses))
  File "<string>", line 2, in filter
  File "/home/holger/git/md_length/venv/lib/python3.5/site-packages/sqlalchemy/orm/base.py", line 198, in generate
    self = args[0]._clone()
  File "/home/holger/git/md_length/venv/lib/python3.5/site-packages/sqlalchemy/orm/dynamic.py", line 289, in _clone
    orm_util.instance_str(instance), self.attr.key))
sqlalchemy.orm.exc.DetachedInstanceError: Parent instance <Department at 0x7f99e6a2fb70> is not bound to a Session, and no contextual session is established; lazy load operation of attribute 'users' cannot proceed (Background on this error at: http://sqlalche.me/e/bhk3)
2019-02-10 09:21:39,214 INFO: Length dep. server startup [in /home/holger/git/labHandle/app/__init__.py:73]
2019-02-10 09:21:54,668 ERROR: Exception on /admin/department [GET] [in /home/holger/.local/lib/python3.5/site-packages/flask/app.py:1761]
Traceback (most recent call last):
  File "/home/holger/.local/lib/python3.5/site-packages/sqlalchemy/util/_collections.py", line 999, in __call__
    return self.registry[key]
KeyError: 140152150615808

During handling of the above exception, another exception occurred:

Traceback (most recent call last):
  File "/home/holger/.local/lib/python3.5/site-packages/flask/app.py", line 2292, in wsgi_app
    response = self.full_dispatch_request()
  File "/home/holger/.local/lib/python3.5/site-packages/flask/app.py", line 1815, in full_dispatch_request
    rv = self.handle_user_exception(e)
  File "/home/holger/.local/lib/python3.5/site-packages/flask/app.py", line 1718, in handle_user_exception
    reraise(exc_type, exc_value, tb)
  File "/home/holger/.local/lib/python3.5/site-packages/flask/_compat.py", line 35, in reraise
    raise value
  File "/home/holger/.local/lib/python3.5/site-packages/flask/app.py", line 1813, in full_dispatch_request
    rv = self.dispatch_request()
  File "/home/holger/.local/lib/python3.5/site-packages/flask/app.py", line 1799, in dispatch_request
    return self.view_functions[rule.endpoint](**req.view_args)
  File "/home/holger/git/labHandle/app/admin/routes.py", line 63, in get_department_list
    data = Department.query.order_by(Department.id).all()
  File "/home/holger/.local/lib/python3.5/site-packages/flask_sqlalchemy/__init__.py", line 514, in __get__
    return type.query_class(mapper, session=self.sa.session())
  File "/home/holger/.local/lib/python3.5/site-packages/sqlalchemy/orm/scoping.py", line 74, in __call__
    return self.registry()
  File "/home/holger/.local/lib/python3.5/site-packages/sqlalchemy/util/_collections.py", line 1001, in __call__
    return self.registry.setdefault(key, self.createfunc())
  File "/home/holger/.local/lib/python3.5/site-packages/sqlalchemy/orm/session.py", line 3010, in __call__
    return self.class_(**local_kw)
  File "/home/holger/.local/lib/python3.5/site-packages/flask_sqlalchemy/__init__.py", line 143, in __init__
    bind = options.pop('bind', None) or db.engine
  File "/home/holger/.local/lib/python3.5/site-packages/flask_sqlalchemy/__init__.py", line 877, in engine
    return self.get_engine()
  File "/home/holger/.local/lib/python3.5/site-packages/flask_sqlalchemy/__init__.py", line 896, in get_engine
    return connector.get_engine()
  File "/home/holger/.local/lib/python3.5/site-packages/flask_sqlalchemy/__init__.py", line 556, in get_engine
    self._sa.apply_driver_hacks(self._app, info, options)
  File "/home/holger/.local/lib/python3.5/site-packages/flask_sqlalchemy/__init__.py", line 830, in apply_driver_hacks
    if info.drivername.startswith('mysql'):
AttributeError: 'NoneType' object has no attribute 'drivername'
2019-02-10 09:36:01,196 INFO: Length dep. server startup [in /home/holger/git/labHandle/app/__init__.py:73]
2019-02-10 09:37:47,460 INFO: Length dep. server startup [in /home/holger/git/labHandle/app/__init__.py:73]
2019-02-10 09:37:55,166 INFO: Length dep. server startup [in /home/holger/git/labHandle/app/__init__.py:73]
2019-02-10 09:38:00,128 INFO: Length dep. server startup [in /home/holger/git/labHandle/app/__init__.py:73]
2019-02-10 09:40:18,718 INFO: Length dep. server startup [in /home/holger/git/labHandle/app/__init__.py:73]
2019-02-10 10:11:01,647 INFO: Length dep. server startup [in /home/holger/git/labHandle/app/__init__.py:73]
