2019-02-27 21:46:05,915 ERROR: Exception on /admin/user [POST] [in /home/holger/.local/lib/python3.5/site-packages/flask/app.py:1761]
Traceback (most recent call last):
  File "/home/holger/.local/lib/python3.5/site-packages/flask/app.py", line 2292, in wsgi_app
    response = self.full_dispatch_request()
  File "/home/holger/.local/lib/python3.5/site-packages/flask/app.py", line 1815, in full_dispatch_request
    rv = self.handle_user_exception(e)
  File "/home/holger/.local/lib/python3.5/site-packages/flask/app.py", line 1718, in handle_user_exception
    reraise(exc_type, exc_value, tb)
  File "/home/holger/.local/lib/python3.5/site-packages/flask/_compat.py", line 35, in reraise
    raise value
  File "/home/holger/.local/lib/python3.5/site-packages/flask/app.py", line 1813, in full_dispatch_request
    rv = self.dispatch_request()
  File "/home/holger/.local/lib/python3.5/site-packages/flask/app.py", line 1799, in dispatch_request
    return self.view_functions[rule.endpoint](**req.view_args)
  File "/home/holger/git/labHandle/app/admin/routes.py", line 37, in add_user
    json_obj = json.loads(request.form.get('form_json'))
  File "/usr/lib/python3.5/json/__init__.py", line 312, in loads
    s.__class__.__name__))
TypeError: the JSON object must be str, not 'NoneType'
2019-02-27 21:49:25,578 INFO: Length dep. server startup [in /home/holger/git/labHandle/app/__init__.py:76]
2019-02-27 21:49:30,512 ERROR: Exception on /admin/user [POST] [in /home/holger/.local/lib/python3.5/site-packages/flask/app.py:1761]
Traceback (most recent call last):
  File "/home/holger/.local/lib/python3.5/site-packages/flask/app.py", line 2292, in wsgi_app
    response = self.full_dispatch_request()
  File "/home/holger/.local/lib/python3.5/site-packages/flask/app.py", line 1815, in full_dispatch_request
    rv = self.handle_user_exception(e)
  File "/home/holger/.local/lib/python3.5/site-packages/flask/app.py", line 1718, in handle_user_exception
    reraise(exc_type, exc_value, tb)
  File "/home/holger/.local/lib/python3.5/site-packages/flask/_compat.py", line 35, in reraise
    raise value
  File "/home/holger/.local/lib/python3.5/site-packages/flask/app.py", line 1813, in full_dispatch_request
    rv = self.dispatch_request()
  File "/home/holger/.local/lib/python3.5/site-packages/flask/app.py", line 1799, in dispatch_request
    return self.view_functions[rule.endpoint](**req.view_args)
  File "/home/holger/git/labHandle/app/admin/routes.py", line 37, in add_user
    json_obj = json.loads(request.form.get('form_json'))
  File "/usr/lib/python3.5/json/__init__.py", line 312, in loads
    s.__class__.__name__))
TypeError: the JSON object must be str, not 'NoneType'
2019-02-27 21:50:04,582 ERROR: Exception on /admin/user [POST] [in /home/holger/.local/lib/python3.5/site-packages/flask/app.py:1761]
Traceback (most recent call last):
  File "/home/holger/.local/lib/python3.5/site-packages/flask/app.py", line 2292, in wsgi_app
    response = self.full_dispatch_request()
  File "/home/holger/.local/lib/python3.5/site-packages/flask/app.py", line 1815, in full_dispatch_request
    rv = self.handle_user_exception(e)
  File "/home/holger/.local/lib/python3.5/site-packages/flask/app.py", line 1718, in handle_user_exception
    reraise(exc_type, exc_value, tb)
  File "/home/holger/.local/lib/python3.5/site-packages/flask/_compat.py", line 35, in reraise
    raise value
  File "/home/holger/.local/lib/python3.5/site-packages/flask/app.py", line 1813, in full_dispatch_request
    rv = self.dispatch_request()
  File "/home/holger/.local/lib/python3.5/site-packages/flask/app.py", line 1799, in dispatch_request
    return self.view_functions[rule.endpoint](**req.view_args)
  File "/home/holger/git/labHandle/app/admin/routes.py", line 37, in add_user
    json_obj = json.loads(request.form.get('form_json'))
  File "/usr/lib/python3.5/json/__init__.py", line 312, in loads
    s.__class__.__name__))
TypeError: the JSON object must be str, not 'NoneType'
2019-02-27 21:52:21,496 INFO: Length dep. server startup [in /home/holger/git/labHandle/app/__init__.py:76]
2019-02-27 22:10:27,300 INFO: Length dep. server startup [in /home/holger/git/labHandle/app/__init__.py:76]
2019-02-27 22:11:38,546 INFO: Length dep. server startup [in /home/holger/git/labHandle/app/__init__.py:76]
2019-02-27 22:11:41,214 ERROR: Exception on /api/users [POST] [in /home/holger/.local/lib/python3.5/site-packages/flask/app.py:1761]
Traceback (most recent call last):
  File "/home/holger/.local/lib/python3.5/site-packages/flask/app.py", line 2292, in wsgi_app
    response = self.full_dispatch_request()
  File "/home/holger/.local/lib/python3.5/site-packages/flask/app.py", line 1815, in full_dispatch_request
    rv = self.handle_user_exception(e)
  File "/home/holger/.local/lib/python3.5/site-packages/flask/app.py", line 1718, in handle_user_exception
    reraise(exc_type, exc_value, tb)
  File "/home/holger/.local/lib/python3.5/site-packages/flask/_compat.py", line 35, in reraise
    raise value
  File "/home/holger/.local/lib/python3.5/site-packages/flask/app.py", line 1813, in full_dispatch_request
    rv = self.dispatch_request()
  File "/home/holger/.local/lib/python3.5/site-packages/flask/app.py", line 1799, in dispatch_request
    return self.view_functions[rule.endpoint](**req.view_args)
  File "/home/holger/git/labHandle/app/api/users.py", line 31, in create_user
    user.add_user(data)
  File "/home/holger/git/labHandle/app/models.py", line 137, in add_user
    set_password(self, user['password'])
NameError: name 'set_password' is not defined
2019-02-27 22:12:00,868 INFO: Length dep. server startup [in /home/holger/git/labHandle/app/__init__.py:76]
2019-02-27 22:12:03,028 ERROR: Exception on /api/users [POST] [in /home/holger/.local/lib/python3.5/site-packages/flask/app.py:1761]
Traceback (most recent call last):
  File "/home/holger/.local/lib/python3.5/site-packages/flask/app.py", line 2292, in wsgi_app
    response = self.full_dispatch_request()
  File "/home/holger/.local/lib/python3.5/site-packages/flask/app.py", line 1815, in full_dispatch_request
    rv = self.handle_user_exception(e)
  File "/home/holger/.local/lib/python3.5/site-packages/flask/app.py", line 1718, in handle_user_exception
    reraise(exc_type, exc_value, tb)
  File "/home/holger/.local/lib/python3.5/site-packages/flask/_compat.py", line 35, in reraise
    raise value
  File "/home/holger/.local/lib/python3.5/site-packages/flask/app.py", line 1813, in full_dispatch_request
    rv = self.dispatch_request()
  File "/home/holger/.local/lib/python3.5/site-packages/flask/app.py", line 1799, in dispatch_request
    return self.view_functions[rule.endpoint](**req.view_args)
  File "/home/holger/git/labHandle/app/api/users.py", line 31, in create_user
    user.add_user(data)
  File "/home/holger/git/labHandle/app/models.py", line 137, in add_user
    self.set_password(self, user['password'])
TypeError: set_password() takes 2 positional arguments but 3 were given
2019-02-27 22:12:19,307 INFO: Length dep. server startup [in /home/holger/git/labHandle/app/__init__.py:76]
2019-02-27 22:12:21,247 ERROR: Exception on /api/users [POST] [in /home/holger/.local/lib/python3.5/site-packages/flask/app.py:1761]
Traceback (most recent call last):
  File "/home/holger/.local/lib/python3.5/site-packages/flask/app.py", line 2292, in wsgi_app
    response = self.full_dispatch_request()
  File "/home/holger/.local/lib/python3.5/site-packages/flask/app.py", line 1815, in full_dispatch_request
    rv = self.handle_user_exception(e)
  File "/home/holger/.local/lib/python3.5/site-packages/flask/app.py", line 1718, in handle_user_exception
    reraise(exc_type, exc_value, tb)
  File "/home/holger/.local/lib/python3.5/site-packages/flask/_compat.py", line 35, in reraise
    raise value
  File "/home/holger/.local/lib/python3.5/site-packages/flask/app.py", line 1813, in full_dispatch_request
    rv = self.dispatch_request()
  File "/home/holger/.local/lib/python3.5/site-packages/flask/app.py", line 1799, in dispatch_request
    return self.view_functions[rule.endpoint](**req.view_args)
  File "/home/holger/git/labHandle/app/api/users.py", line 32, in create_user
    res = User.query.filter_by(username=data['username']).first_on_404
AttributeError: 'BaseQuery' object has no attribute 'first_on_404'
2019-02-27 22:14:08,581 INFO: Length dep. server startup [in /home/holger/git/labHandle/app/__init__.py:76]
2019-02-27 22:14:32,640 ERROR: Exception on /api/users [POST] [in /home/holger/.local/lib/python3.5/site-packages/flask/app.py:1761]
Traceback (most recent call last):
  File "/home/holger/.local/lib/python3.5/site-packages/flask/app.py", line 2292, in wsgi_app
    response = self.full_dispatch_request()
  File "/home/holger/.local/lib/python3.5/site-packages/flask/app.py", line 1815, in full_dispatch_request
    rv = self.handle_user_exception(e)
  File "/home/holger/.local/lib/python3.5/site-packages/flask/app.py", line 1718, in handle_user_exception
    reraise(exc_type, exc_value, tb)
  File "/home/holger/.local/lib/python3.5/site-packages/flask/_compat.py", line 35, in reraise
    raise value
  File "/home/holger/.local/lib/python3.5/site-packages/flask/app.py", line 1813, in full_dispatch_request
    rv = self.dispatch_request()
  File "/home/holger/.local/lib/python3.5/site-packages/flask/app.py", line 1799, in dispatch_request
    return self.view_functions[rule.endpoint](**req.view_args)
  File "/home/holger/git/labHandle/app/api/users.py", line 32, in create_user
    res = User.query.filter_by(username=data['username']).first_or_none()
AttributeError: 'BaseQuery' object has no attribute 'first_or_none'
2019-02-27 22:14:49,740 INFO: Length dep. server startup [in /home/holger/git/labHandle/app/__init__.py:76]
2019-02-27 22:17:00,603 INFO: Length dep. server startup [in /home/holger/git/labHandle/app/__init__.py:76]
