2019-01-10 10:00:13,292 ERROR: Exception on /search [GET] [in c:\users\holger\documents\git\proto_qry\venv\lib\site-packages\flask\app.py:1761]
Traceback (most recent call last):
  File "c:\users\holger\documents\git\proto_qry\venv\lib\site-packages\flask\app.py", line 2292, in wsgi_app
    response = self.full_dispatch_request()
  File "c:\users\holger\documents\git\proto_qry\venv\lib\site-packages\flask\app.py", line 1815, in full_dispatch_request
    rv = self.handle_user_exception(e)
  File "c:\users\holger\documents\git\proto_qry\venv\lib\site-packages\flask\app.py", line 1718, in handle_user_exception
    reraise(exc_type, exc_value, tb)
  File "c:\users\holger\documents\git\proto_qry\venv\lib\site-packages\flask\_compat.py", line 35, in reraise
    raise value
  File "c:\users\holger\documents\git\proto_qry\venv\lib\site-packages\flask\app.py", line 1813, in full_dispatch_request
    rv = self.dispatch_request()
  File "c:\users\holger\documents\git\proto_qry\venv\lib\site-packages\flask\app.py", line 1799, in dispatch_request
    return self.view_functions[rule.endpoint](**req.view_args)
  File "C:\Users\holger\Documents\git\proto_qry\app\main\routes.py", line 25, in search
    print(res.json())
  File "C:\Users\holger\Documents\git\proto_qry\app\models.py", line 49, in json
    return to_json(self, self.__class__)
  File "C:\Users\holger\Documents\git\proto_qry\app\models.py", line 30, in to_json
    return json.dumps(d)
  File "C:\Python35-32\lib\json\__init__.py", line 230, in dumps
    return _default_encoder.encode(obj)
  File "C:\Python35-32\lib\json\encoder.py", line 198, in encode
    chunks = self.iterencode(o, _one_shot=True)
  File "C:\Python35-32\lib\json\encoder.py", line 256, in iterencode
    return _iterencode(o, 0)
  File "C:\Python35-32\lib\json\encoder.py", line 179, in default
    raise TypeError(repr(o) + " is not JSON serializable")
TypeError: datetime.datetime(2018, 12, 14, 14, 47, 22) is not JSON serializable
2019-01-10 10:00:45,459 INFO: Protocol data qry server startup [in C:\Users\holger\Documents\git\proto_qry\app\__init__.py:48]
2019-01-10 10:00:48,423 ERROR: Exception on /search [GET] [in c:\users\holger\documents\git\proto_qry\venv\lib\site-packages\flask\app.py:1761]
Traceback (most recent call last):
  File "c:\users\holger\documents\git\proto_qry\venv\lib\site-packages\flask\app.py", line 2292, in wsgi_app
    response = self.full_dispatch_request()
  File "c:\users\holger\documents\git\proto_qry\venv\lib\site-packages\flask\app.py", line 1815, in full_dispatch_request
    rv = self.handle_user_exception(e)
  File "c:\users\holger\documents\git\proto_qry\venv\lib\site-packages\flask\app.py", line 1718, in handle_user_exception
    reraise(exc_type, exc_value, tb)
  File "c:\users\holger\documents\git\proto_qry\venv\lib\site-packages\flask\_compat.py", line 35, in reraise
    raise value
  File "c:\users\holger\documents\git\proto_qry\venv\lib\site-packages\flask\app.py", line 1813, in full_dispatch_request
    rv = self.dispatch_request()
  File "c:\users\holger\documents\git\proto_qry\venv\lib\site-packages\flask\app.py", line 1799, in dispatch_request
    return self.view_functions[rule.endpoint](**req.view_args)
  File "C:\Users\holger\Documents\git\proto_qry\app\main\routes.py", line 25, in search
    print(res.json())
  File "C:\Users\holger\Documents\git\proto_qry\app\models.py", line 49, in json
    return to_json(self, self.__class__)
  File "C:\Users\holger\Documents\git\proto_qry\app\models.py", line 30, in to_json
    return json.dumps(d)
  File "C:\Python35-32\lib\json\__init__.py", line 230, in dumps
    return _default_encoder.encode(obj)
  File "C:\Python35-32\lib\json\encoder.py", line 198, in encode
    chunks = self.iterencode(o, _one_shot=True)
  File "C:\Python35-32\lib\json\encoder.py", line 256, in iterencode
    return _iterencode(o, 0)
  File "C:\Python35-32\lib\json\encoder.py", line 179, in default
    raise TypeError(repr(o) + " is not JSON serializable")
TypeError: datetime.datetime(2018, 12, 14, 14, 47, 22) is not JSON serializable
2019-01-10 10:03:03,658 INFO: Protocol data qry server startup [in C:\Users\holger\Documents\git\proto_qry\app\__init__.py:48]
2019-01-10 10:03:06,341 ERROR: Exception on /search [GET] [in c:\users\holger\documents\git\proto_qry\venv\lib\site-packages\flask\app.py:1761]
Traceback (most recent call last):
  File "c:\users\holger\documents\git\proto_qry\venv\lib\site-packages\flask\app.py", line 2292, in wsgi_app
    response = self.full_dispatch_request()
  File "c:\users\holger\documents\git\proto_qry\venv\lib\site-packages\flask\app.py", line 1815, in full_dispatch_request
    rv = self.handle_user_exception(e)
  File "c:\users\holger\documents\git\proto_qry\venv\lib\site-packages\flask\app.py", line 1718, in handle_user_exception
    reraise(exc_type, exc_value, tb)
  File "c:\users\holger\documents\git\proto_qry\venv\lib\site-packages\flask\_compat.py", line 35, in reraise
    raise value
  File "c:\users\holger\documents\git\proto_qry\venv\lib\site-packages\flask\app.py", line 1813, in full_dispatch_request
    rv = self.dispatch_request()
  File "c:\users\holger\documents\git\proto_qry\venv\lib\site-packages\flask\app.py", line 1799, in dispatch_request
    return self.view_functions[rule.endpoint](**req.view_args)
  File "C:\Users\holger\Documents\git\proto_qry\app\main\routes.py", line 25, in search
    print(res.json())
  File "C:\Users\holger\Documents\git\proto_qry\app\models.py", line 56, in json
    return json.dumps(out)
  File "C:\Python35-32\lib\json\__init__.py", line 230, in dumps
    return _default_encoder.encode(obj)
  File "C:\Python35-32\lib\json\encoder.py", line 198, in encode
    chunks = self.iterencode(o, _one_shot=True)
  File "C:\Python35-32\lib\json\encoder.py", line 256, in iterencode
    return _iterencode(o, 0)
  File "C:\Python35-32\lib\json\encoder.py", line 179, in default
    raise TypeError(repr(o) + " is not JSON serializable")
TypeError: datetime.datetime(2018, 12, 14, 14, 47, 22) is not JSON serializable
2019-01-10 10:04:19,859 INFO: Protocol data qry server startup [in C:\Users\holger\Documents\git\proto_qry\app\__init__.py:48]
2019-01-10 10:04:26,287 INFO: Protocol data qry server startup [in C:\Users\holger\Documents\git\proto_qry\app\__init__.py:48]
2019-01-10 10:06:59,790 INFO: Protocol data qry server startup [in C:\Users\holger\Documents\git\proto_qry\app\__init__.py:48]
2019-01-10 10:07:58,073 INFO: Protocol data qry server startup [in C:\Users\holger\Documents\git\proto_qry\app\__init__.py:48]
2019-01-10 10:08:32,018 INFO: Protocol data qry server startup [in C:\Users\holger\Documents\git\proto_qry\app\__init__.py:48]
2019-01-10 10:12:23,913 INFO: Protocol data qry server startup [in C:\Users\holger\Documents\git\proto_qry\app\__init__.py:48]
2019-01-10 10:12:26,909 ERROR: Exception on /search [GET] [in c:\users\holger\documents\git\proto_qry\venv\lib\site-packages\flask\app.py:1761]
Traceback (most recent call last):
  File "c:\users\holger\documents\git\proto_qry\venv\lib\site-packages\flask\app.py", line 2292, in wsgi_app
    response = self.full_dispatch_request()
  File "c:\users\holger\documents\git\proto_qry\venv\lib\site-packages\flask\app.py", line 1815, in full_dispatch_request
    rv = self.handle_user_exception(e)
  File "c:\users\holger\documents\git\proto_qry\venv\lib\site-packages\flask\app.py", line 1718, in handle_user_exception
    reraise(exc_type, exc_value, tb)
  File "c:\users\holger\documents\git\proto_qry\venv\lib\site-packages\flask\_compat.py", line 35, in reraise
    raise value
  File "c:\users\holger\documents\git\proto_qry\venv\lib\site-packages\flask\app.py", line 1813, in full_dispatch_request
    rv = self.dispatch_request()
  File "c:\users\holger\documents\git\proto_qry\venv\lib\site-packages\flask\app.py", line 1799, in dispatch_request
    return self.view_functions[rule.endpoint](**req.view_args)
  File "C:\Users\holger\Documents\git\proto_qry\app\main\routes.py", line 25, in search
    print(res.repr())
AttributeError: 'Odm_data' object has no attribute 'repr'
2019-01-10 10:12:57,547 INFO: Protocol data qry server startup [in C:\Users\holger\Documents\git\proto_qry\app\__init__.py:48]
2019-01-10 10:13:21,290 INFO: Protocol data qry server startup [in C:\Users\holger\Documents\git\proto_qry\app\__init__.py:48]
2019-01-10 16:27:38,277 INFO: Protocol data qry server startup [in C:\Users\holger\Documents\git\proto_qry\app\__init__.py:48]
2019-01-10 16:28:54,223 INFO: Protocol data qry server startup [in C:\Users\holger\Documents\git\proto_qry\app\__init__.py:48]
2019-01-10 16:28:57,031 ERROR: Exception on / [GET] [in c:\users\holger\documents\git\proto_qry\venv\lib\site-packages\flask\app.py:1761]
Traceback (most recent call last):
  File "c:\users\holger\documents\git\proto_qry\venv\lib\site-packages\flask\app.py", line 2292, in wsgi_app
    response = self.full_dispatch_request()
  File "c:\users\holger\documents\git\proto_qry\venv\lib\site-packages\flask\app.py", line 1815, in full_dispatch_request
    rv = self.handle_user_exception(e)
  File "c:\users\holger\documents\git\proto_qry\venv\lib\site-packages\flask\app.py", line 1718, in handle_user_exception
    reraise(exc_type, exc_value, tb)
  File "c:\users\holger\documents\git\proto_qry\venv\lib\site-packages\flask\_compat.py", line 35, in reraise
    raise value
  File "c:\users\holger\documents\git\proto_qry\venv\lib\site-packages\flask\app.py", line 1813, in full_dispatch_request
    rv = self.dispatch_request()
  File "c:\users\holger\documents\git\proto_qry\venv\lib\site-packages\flask\app.py", line 1799, in dispatch_request
    return self.view_functions[rule.endpoint](**req.view_args)
  File "C:\Users\holger\Documents\git\proto_qry\app\main\routes.py", line 12, in index
    data_list = Odm_data.query().all()
TypeError: 'BaseQuery' object is not callable
2019-01-10 16:29:08,169 INFO: Protocol data qry server startup [in C:\Users\holger\Documents\git\proto_qry\app\__init__.py:48]
