2019-01-09 16:17:40,429 ERROR: Exception on /search [GET] [in c:\users\holger\documents\git\gitlab_internal\proto_qry\venv\lib\site-packages\flask\app.py:1761]
Traceback (most recent call last):
  File "c:\users\holger\documents\git\gitlab_internal\proto_qry\venv\lib\site-packages\sqlalchemy\engine\base.py", line 1193, in _execute_context
    context)
  File "c:\users\holger\documents\git\gitlab_internal\proto_qry\venv\lib\site-packages\sqlalchemy\engine\default.py", line 509, in do_execute
    cursor.execute(statement, parameters)
  File "c:\users\holger\documents\git\gitlab_internal\proto_qry\venv\lib\site-packages\pymysql\cursors.py", line 170, in execute
    result = self._query(query)
  File "c:\users\holger\documents\git\gitlab_internal\proto_qry\venv\lib\site-packages\pymysql\cursors.py", line 328, in _query
    conn.query(q)
  File "c:\users\holger\documents\git\gitlab_internal\proto_qry\venv\lib\site-packages\pymysql\connections.py", line 517, in query
    self._affected_rows = self._read_query_result(unbuffered=unbuffered)
  File "c:\users\holger\documents\git\gitlab_internal\proto_qry\venv\lib\site-packages\pymysql\connections.py", line 732, in _read_query_result
    result.read()
  File "c:\users\holger\documents\git\gitlab_internal\proto_qry\venv\lib\site-packages\pymysql\connections.py", line 1075, in read
    first_packet = self.connection._read_packet()
  File "c:\users\holger\documents\git\gitlab_internal\proto_qry\venv\lib\site-packages\pymysql\connections.py", line 684, in _read_packet
    packet.check_error()
  File "c:\users\holger\documents\git\gitlab_internal\proto_qry\venv\lib\site-packages\pymysql\protocol.py", line 220, in check_error
    err.raise_mysql_exception(self._data)
  File "c:\users\holger\documents\git\gitlab_internal\proto_qry\venv\lib\site-packages\pymysql\err.py", line 109, in raise_mysql_exception
    raise errorclass(errno, errval)
pymysql.err.ProgrammingError: (1146, "Table 'docman.odmfile' doesn't exist")

The above exception was the direct cause of the following exception:

Traceback (most recent call last):
  File "c:\users\holger\documents\git\gitlab_internal\proto_qry\venv\lib\site-packages\flask\app.py", line 2292, in wsgi_app
    response = self.full_dispatch_request()
  File "c:\users\holger\documents\git\gitlab_internal\proto_qry\venv\lib\site-packages\flask\app.py", line 1815, in full_dispatch_request
    rv = self.handle_user_exception(e)
  File "c:\users\holger\documents\git\gitlab_internal\proto_qry\venv\lib\site-packages\flask\app.py", line 1718, in handle_user_exception
    reraise(exc_type, exc_value, tb)
  File "c:\users\holger\documents\git\gitlab_internal\proto_qry\venv\lib\site-packages\flask\_compat.py", line 35, in reraise
    raise value
  File "c:\users\holger\documents\git\gitlab_internal\proto_qry\venv\lib\site-packages\flask\app.py", line 1813, in full_dispatch_request
    rv = self.dispatch_request()
  File "c:\users\holger\documents\git\gitlab_internal\proto_qry\venv\lib\site-packages\flask\app.py", line 1799, in dispatch_request
    return self.view_functions[rule.endpoint](**req.view_args)
  File "C:\Users\holger\Documents\git\gitlab_internal\proto_qry\app\main\routes.py", line 22, in search
    res = Odmfile.query.filter_by(realname=file).first()
  File "c:\users\holger\documents\git\gitlab_internal\proto_qry\venv\lib\site-packages\sqlalchemy\orm\query.py", line 2895, in first
    ret = list(self[0:1])
  File "c:\users\holger\documents\git\gitlab_internal\proto_qry\venv\lib\site-packages\sqlalchemy\orm\query.py", line 2687, in __getitem__
    return list(res)
  File "c:\users\holger\documents\git\gitlab_internal\proto_qry\venv\lib\site-packages\sqlalchemy\orm\query.py", line 2995, in __iter__
    return self._execute_and_instances(context)
  File "c:\users\holger\documents\git\gitlab_internal\proto_qry\venv\lib\site-packages\sqlalchemy\orm\query.py", line 3018, in _execute_and_instances
    result = conn.execute(querycontext.statement, self._params)
  File "c:\users\holger\documents\git\gitlab_internal\proto_qry\venv\lib\site-packages\sqlalchemy\engine\base.py", line 948, in execute
    return meth(self, multiparams, params)
  File "c:\users\holger\documents\git\gitlab_internal\proto_qry\venv\lib\site-packages\sqlalchemy\sql\elements.py", line 269, in _execute_on_connection
    return connection._execute_clauseelement(self, multiparams, params)
  File "c:\users\holger\documents\git\gitlab_internal\proto_qry\venv\lib\site-packages\sqlalchemy\engine\base.py", line 1060, in _execute_clauseelement
    compiled_sql, distilled_params
  File "c:\users\holger\documents\git\gitlab_internal\proto_qry\venv\lib\site-packages\sqlalchemy\engine\base.py", line 1200, in _execute_context
    context)
  File "c:\users\holger\documents\git\gitlab_internal\proto_qry\venv\lib\site-packages\sqlalchemy\engine\base.py", line 1413, in _handle_dbapi_exception
    exc_info
  File "c:\users\holger\documents\git\gitlab_internal\proto_qry\venv\lib\site-packages\sqlalchemy\util\compat.py", line 265, in raise_from_cause
    reraise(type(exception), exception, tb=exc_tb, cause=cause)
  File "c:\users\holger\documents\git\gitlab_internal\proto_qry\venv\lib\site-packages\sqlalchemy\util\compat.py", line 248, in reraise
    raise value.with_traceback(tb)
  File "c:\users\holger\documents\git\gitlab_internal\proto_qry\venv\lib\site-packages\sqlalchemy\engine\base.py", line 1193, in _execute_context
    context)
  File "c:\users\holger\documents\git\gitlab_internal\proto_qry\venv\lib\site-packages\sqlalchemy\engine\default.py", line 509, in do_execute
    cursor.execute(statement, parameters)
  File "c:\users\holger\documents\git\gitlab_internal\proto_qry\venv\lib\site-packages\pymysql\cursors.py", line 170, in execute
    result = self._query(query)
  File "c:\users\holger\documents\git\gitlab_internal\proto_qry\venv\lib\site-packages\pymysql\cursors.py", line 328, in _query
    conn.query(q)
  File "c:\users\holger\documents\git\gitlab_internal\proto_qry\venv\lib\site-packages\pymysql\connections.py", line 517, in query
    self._affected_rows = self._read_query_result(unbuffered=unbuffered)
  File "c:\users\holger\documents\git\gitlab_internal\proto_qry\venv\lib\site-packages\pymysql\connections.py", line 732, in _read_query_result
    result.read()
  File "c:\users\holger\documents\git\gitlab_internal\proto_qry\venv\lib\site-packages\pymysql\connections.py", line 1075, in read
    first_packet = self.connection._read_packet()
  File "c:\users\holger\documents\git\gitlab_internal\proto_qry\venv\lib\site-packages\pymysql\connections.py", line 684, in _read_packet
    packet.check_error()
  File "c:\users\holger\documents\git\gitlab_internal\proto_qry\venv\lib\site-packages\pymysql\protocol.py", line 220, in check_error
    err.raise_mysql_exception(self._data)
  File "c:\users\holger\documents\git\gitlab_internal\proto_qry\venv\lib\site-packages\pymysql\err.py", line 109, in raise_mysql_exception
    raise errorclass(errno, errval)
sqlalchemy.exc.ProgrammingError: (pymysql.err.ProgrammingError) (1146, "Table 'docman.odmfile' doesn't exist") [SQL: 'SELECT odmfile.id AS odmfile_id, odmfile.category AS odmfile_category, odmfile.owner AS odmfile_owner, odmfile.realname AS odmfile_realname, odmfile.description AS odmfile_description, odmfile.comment AS odmfile_comment, odmfile.reviewer_comments AS odmfile_reviewer_comments, odmfile.created AS odmfile_created, odmfile.status AS odmfile_status, odmfile.department AS odmfile_department, odmfile.default_rights AS odmfile_default_rights, odmfile.publishable AS odmfile_publishable, odmfile.reviewer AS odmfile_reviewer \nFROM odmfile \nWHERE odmfile.realname = %(realname_1)s \n LIMIT %(param_1)s'] [parameters: {'param_1': 1, 'realname_1': "'Nihik-14-12-2018.xlsx'"}] (Background on this error at: http://sqlalche.me/e/f405)
2019-01-09 16:18:37,369 INFO: Protocol data qry server startup [in C:\Users\holger\Documents\git\gitlab_internal\proto_qry\app\__init__.py:48]
2019-01-09 16:18:42,019 ERROR: Exception on /search [GET] [in c:\users\holger\documents\git\gitlab_internal\proto_qry\venv\lib\site-packages\flask\app.py:1761]
Traceback (most recent call last):
  File "c:\users\holger\documents\git\gitlab_internal\proto_qry\venv\lib\site-packages\flask\app.py", line 2292, in wsgi_app
    response = self.full_dispatch_request()
  File "c:\users\holger\documents\git\gitlab_internal\proto_qry\venv\lib\site-packages\flask\app.py", line 1815, in full_dispatch_request
    rv = self.handle_user_exception(e)
  File "c:\users\holger\documents\git\gitlab_internal\proto_qry\venv\lib\site-packages\flask\app.py", line 1718, in handle_user_exception
    reraise(exc_type, exc_value, tb)
  File "c:\users\holger\documents\git\gitlab_internal\proto_qry\venv\lib\site-packages\flask\_compat.py", line 35, in reraise
    raise value
  File "c:\users\holger\documents\git\gitlab_internal\proto_qry\venv\lib\site-packages\flask\app.py", line 1813, in full_dispatch_request
    rv = self.dispatch_request()
  File "c:\users\holger\documents\git\gitlab_internal\proto_qry\venv\lib\site-packages\flask\app.py", line 1799, in dispatch_request
    return self.view_functions[rule.endpoint](**req.view_args)
  File "C:\Users\holger\Documents\git\gitlab_internal\proto_qry\app\main\routes.py", line 22, in search
    res = Odmfile.query.filter_by(realname=file).first()
NameError: name 'Odmfile' is not defined
2019-01-09 16:18:57,962 INFO: Protocol data qry server startup [in C:\Users\holger\Documents\git\gitlab_internal\proto_qry\app\__init__.py:48]
